Workbook
Name JobList_JOBID: #REF!
Name JobList_JOBID: #REF!
Name JobList_SID: #REF!
Name JobList_SID: #REF!
Name TECHNICIAN: #REF!
Name JobList_JOBID: #REF!
Name JobList_SID: #REF!
Name JobList_JOBID: #REF!
Name JobList_SID: #REF!

Sheet stg_contract_values
A1: Contract # | B1: Contract Status | C1: Contract Execution Date | D1: Contract Expiration Date | E1: Contract Home Multiplier | F1: Contract Field Multiplier | G1: Contract Value
A2: C000015869 | B2: Closed | C2: 44621 | D2: 45716 | E2: 2.75 | F2: 2.54 | G2: 6000000
A3: C000015128 | B3: Closed | C3: 43424 | D3: 44519 | E3: 2.51 | F3: 2.41 | G3: 6000000
A4: C000016435 | B4: Open | C4: 45728 | D4: 46823 | E4: 3 | F4: 2.93 | G4: 5000000

Sheet stg_sca_rfp
A1: BuildingID | B1: Project _D | C1: Project Descriptio | D1: ServiceID | E1: ServiceName | F1: InitiationDate | G1: PrimaryHygienist | H1: WA_Number | I1: ContractNo | J1: RFPNo | K1: IsFinal | L1: RFP_Status | M1: RFP_Status_Date | N1: eRFP_Status | O1: eRFP_Status_Date | P1: RFPDate
A2: M180 | B2: 141149 | C2: PO18-ABATEMENT OF PIPE INSULATION ENTRANCE OF BOILER RM WE ARE GOING TO NEED APPROXIMATELY 10' OF CO | D2: 93632 | E2: PO 18 Asbestos Service | F2: 45573 | G2: Lazicki, Rafal | H2: 1315970 | I2: C000015869 | J2: 202 | K2: Y | L2: Check Issued | M2: 45888 | N2: Closed | O2: 45888 | P2: =DATE(YEAR(O2),MONTH(O2),DAY(O2)) -> 45888
A3: R455 | B3: 135678 | C3: PO18-ASSIST PLUMBERS: OPEN A 3FT X 8FT CIELING SPRAYED IN RED. ALSO REMOVE ALL LOOSE ACM IN CIELING | D3: 88731 | E3: PO 18 Asbestos Service | F3: 45120 | G3: Bracamonte, Jesus | H3: 1187909 | I3: C000015869 | J3: 224 | K3: Y | L3: Check Issued | M3: 45888 | N3: Closed | O3: 45888 | P3: =DATE(YEAR(O3),MONTH(O3),DAY(O3)) -> 45888
A4: K014 | B4: P026159 | C4: RESO A AUDITORIUM UPGRADE | D4: 85451 | E4: LAP Construction Phase Services | F4: 44741 | G4: Clyne, Sean | H4: 1129904 | I4: C000015869 | J4: 305 | K4: Y | L4: Check Issued | M4: 46018 | N4: Closed | O4: 46018 | P4: =DATE(YEAR(O4),MONTH(O4),DAY(O4)) -> 46018
A5: Q189 | B5: 133460 | C5: PO18-05/25Q189/ BOILER #3 ABATE 1 SQUARE FOOT OF ACM, SPRAYED IN GREEN | D5: 86933 | E5: PO 18 Asbestos Service | F5: 44910 | G5: Kondilis, Milton | H5: 1157908 | I5: C000015869 | J5: 312 | K5: Y | L5: Check Issued | M5: 46100 | N5: Closed | O5: 46100 | P5: =DATE(YEAR(O5),MONTH(O5),DAY(O5)) -> 46100
A6: X107 | B6: 141770 | C6: PO18-ABATE AND REPAIR DAMAGED PIPE INSULATION 1000, 3218 ABATE AND REPLACE FLOOR TILES 1001S, 2106, | D6: 94758 | E6: PO 18 Asbestos Service | F6: 45695 | G6: Bracamonte, Jesus | H6: 1334935 | I6: C000015869 | J6: 319 | K6: Y | L6: Check Issued | M6: 46165 | N6: Closed | O6: 46165 | P6: =DATE(YEAR(O6),MONTH(O6),DAY(O6)) -> 46165

Sheet stg_sca_fixed_prices
A1: Contract No | B1: Work Type Code | C1: Work Type Desc | D1: Fixed Price | E1: Status Date
A2: C000016435 | B2: LAMP48 | C2: Lead Wipe Clearance - CIP & Capacity | D2: 375 | E2: 45126
A3: C000016435 | B3: LAMP19 | C3: Lead Wipe Clearance - PO18 | D3: 375 | E3: 45126
A4: C000016435 | B4: LAMP18 | C4: Project Records Package Review | D4: 375 | E4: 45126
A5: C000016435 | B5: LAMP23 | C5: Emergency Site Visit | D5: 375 | E5: 45126
A6: C000016435 | B6: LAMP20 | C6: PO18 Survey | D6: 750 | E6: 45126
A7: C000016435 | B7: LAMP05 | C7: PO18 Cores | D7: 650 | E7: 45126
A8: C000016435 | B8: LAMP21 | C8: Mold Survey | D8: 750 | E8: 45126
A9: C000016435 | B9: LCS149 | C9: ACP5 Fee | D9: 500 | E9: 45126
A10: C000016435 | B10: LCS152 | C10: CTF/Small Cap/Local Law Asbestos Survey | D10: 750 | E10: 45126
A11: C000016435 | B11: LAMP1000 | C11: No Sampling Required Rate for Service | D11: 750 | E11: 45126
A12: C000015128 | B12: LAMP48 | C12: Lead Wipe Clearance - CIP & Capacity | D12: 250 | E12: 41923
A13: C000015128 | B13: LAMP19 | C13: Lead Wipe Clearance - PO18 | D13: 250 | E13: 41923
... A31: C000015869 | B31: LAMP1000 | C31: No Sampling Required Rate for Service | D31: 500 | E31: 44271

Sheet stg_sca_wa
A1: Building Id | B1: Building Name | C1: Building Address | D1: Project ID | E1: Project Name | F1: Project Type | G1: Service ID | H1: Service Name | I1: Service Initiation Date | J1: Priority | K1: Primary Hygienist | L1: Contract_No | M1: WA_No | N1: WA Type | O1: Date WA Issued | P1: WA Status | Q1: Status Date | R1: Expected Due Date | S1: Original WA Amt | T1: Current Approved Amt | U1: Proposed Amendment Amt | V1: WA_Total_Amt
A2: X107 | B2: P.S. 107 - BRONX | C2: 1695 SEWARD AVENUE | D2: 141770 | E2: PO18-ABATE AND REPAIR DAMAGED PIPE INSULATION 1000, 3218 ABATE AND REPLACE FLOOR TILES 1001S, 2106, | F2: CIP | G2: 94758 | H2: PO 18 Asbestos Service | I2: 45695 | J2: Emergency | K2: Bracamonte, Jesus | L2: C000015869 | M2: 1334935 | N2: RFA | O2: 45695 | P2: Closed | Q2: 46165 | S2: 575 | T2: 39440.45 | U2: 0 | V2: 39440.45
A3: M180 | B3: P.S. 180 - MANHATTAN | C3: 370 WEST 120 STREET | D3: 141149 | E3: PO18-ABATEMENT OF PIPE INSULATION ENTRANCE OF BOILER RM WE ARE GOING TO NEED APPROXIMATELY 10' OF CO | F3: CIP | G3: 93632 | H3: PO 18 Asbestos Service | I3: 45573 | J3: Emergency | K3: Lazicki, Rafal | L3: C000015869 | M3: 1315970 | N3: RFA | O3: 45575 | P3: Closed | Q3: 45888 | S3: 575 | T3: 4759.59 | U3: 0 | V3: 4759.59
A4: R455 | B4: TOTTENVILLE HS - STATEN ISLAND | C4: 100 LUTEN AVENUE | D4: 135678 | E4: PO18-ASSIST PLUMBERS: OPEN A 3FT X 8FT CIELING SPRAYED IN RED. ALSO REMOVE ALL LOOSE ACM IN CIELING | F4: CIP | G4: 88731 | H4: PO 18 Asbestos Service | I4: 45120 | J4: Emergency | K4: Bracamonte, Jesus | L4: C000015869 | M4: 1187909 | N4: RFA | O4: 45120 | P4: Closed | Q4: 45888 | S4: 7875 | T4: 2628.23 | U4: 0 | V4: 2628.23
A5: Q189 | B5: J.H.S. 189 - QUEENS | C5: 144-80 BARCLAY AVENUE | D5: 133460 | E5: PO18-05/25Q189/ BOILER #3 ABATE 1 SQUARE FOOT OF ACM, SPRAYED IN GREEN | F5: CIP | G5: 86933 | H5: PO 18 Asbestos Service | I5: 44910 | J5: Emergency | K5: Kondilis, Milton | L5: C000015869 | M5: 1157908 | N5: RFA | O5: 44910 | P5: Closed | Q5: 46100 | S5: 3200 | T5: 1867.45 | U5: 0 | V5: 1867.45
A6: K014 | B6: I.S. 14 - BROOKLYN | C6: 2424 BATCHELDER STREET | D6: P026159 | E6: RESO A AUDITORIUM UPGRADE | F6: CIP | G6: 85451 | H6: LAP Construction Phase Services | I6: 44741 | J6: Normal | K6: Clyne, Sean | L6: C000015869 | M6: 1129904 | N6: RFA | O6: 44749 | P6: Closed | Q6: 46018 | S6: 9700 | T6: 3108.44 | U6: 0 | V6: 3108.44

Sheet stg_monthly_status
A1: JobID | B1: Contract_No | C1: BuildingID | D1: School_Name | E1: WA_NO | F1: Service_ID | G1: Project Type | H1: Primary_Hygienist | I1: Service_Name | J1: WA Type | K1: WA Status | L1: Initiation_Date | M1: WA_Estimate_Cost | N1: Actual Start Date (RFP) | O1: Actual Date of Completion (RFP) | P1: RFP_No | Q1: RFP_Date | R1: Amount_Invoiced | S1: Amount_Received | T1: Amount Outstanding | U1: Check_No | V1: DATE ON CHECK | W1: DATE CHECK RECEIVED | X1: Billing_Status
A2: 17SD-136 | B2: C000013440 | C2: M470 | D2: LOUIS D. BRANDEIS HS - MANHATTAN | E2: 888431 | F2: 68127 | G2: CIP | H2: Langlois, Bret | I2: LAP Design Review & Specification | J2: Amendment | K2: WIP | L2: 43046 | M2: 3575 | S2: 0 | T2: 0 | X2: NOT BILLED
A3: 21S-100 | B3: C000015128 | C3: K186 | D3: P.S. 186 - BROOKLYN | E3: 1097498 | F3: 82916 | G3: CIP | H3: Scott, Richard | I3: PO 18 Asbestos Service | J3: Amendment | K3: WIP | L3: 44505 | M3: 10700 | S3: 0 | T3: 0 | X3: NOT BILLED
A4: 24S-077 | B4: C000015128 | C4: Q089 | D4: P.S. 89 - QUEENS | E4: 1302817 | F4: 92921 | G4: CIP | H4: Poskrobko, Lukasz | I4: PO 18 Asbestos Service | J4: Initial | K4: Closed | L4: 45513 | M4: 575 | N4: 45514 | O4: 45515 | P4: 327 | Q4: 46175 | R4: 2774.69 | S4: 0 | T4: -2774.69 | X4: UNPAID
A5: 21S-105 | B5: C000015128 | C5: X405 | D5: HERBERT H. LEHMAN HS - BRONX | E5: 1098818 | F5: 83582 | G5: CIP | H5: Alawamleh, Eman | I5: LAP Construction Phase Services | J5: Initial | K5: WIP | L5: 44516 | M5: 500 | S5: 0 | T5: 0 | X5: NOT BILLED
A6: 22S-029 | B6: C000015869 | C6: K014 | D6: I.S. 14 - BROOKLYN | E6: 1129904 | F6: 85451 | G6: CIP | H6: Clyne, Sean | I6: LAP Construction Phase Services | J6: Initial | K6: Closed | L6: 44754 | M6: 9700 | N6: 44749 | O6: 44758 | P6: 305 | Q6: 46000 | R6: 3108.44 | S6: 3108.44 | T6: 0 | U6: 700005330 | V6: 46019 | W6: 46021 | X6: PAID
A7: 24S-128 | B7: C000015869 | C7: K043 | D7: I.S. 98 - BROOKLYN | E7: 1320962 | F7: 93925 | G7: CIP | H7: Bracamonte, Jesus | I7: Special Program | J7: Initial | K7: Initial | L7: 45609 | M7: 4100 | S7: 0 | T7: 0 | X7: NOT BILLED
B8: C000015869 | C8: K102 | D8: P.S. 102 - BROOKLYN | E8: 1306782 | F8: 92043 | G8: CIP | H8: Scott, Richard | I8: PO 18 Asbestos Service | J8: Initial | K8: Initial | L8: 45533 | M8: 575 | S8: 0 | T8: 0 | X8: NOT BILLED
A9: 25S-012 | B9: C000015869 | C9: K138 | D9: P.S. 138 - BROOKLYN | E9: 1335922 | F9: 94843 | G9: CIP | H9: Palermo, Albert | I9: PO 18 Asbestos Service | J9: Initial | K9: Initial | L9: 45701 | M9: 6275 | S9: 0 | T9: 0 | X9: NOT BILLED
A10: 24S-061 | B10: C000015869 | C10: K151 | D10: P.S. 151 - BROOKLYN | E10: 1302568 | F10: 92321 | G10: CIP | H10: Walsh, Joseph | I10: PO 18 Asbestos Service | J10: Initial | K10: Initial | L10: 45509 | M10: 575 | S10: 0 | T10: 0 | X10: NOT BILLED
A11: 24S-014 | B11: C000015869 | C11: K160 | D11: P.S. 160 - BROOKLYN | E11: 1222094 | F11: 90892 | G11: CIP | H11: Scott, Richard | I11: PO 18 Asbestos Service | J11: Initial | K11: Initial | L11: 45350 | M11: 575 | S11: 0 | T11: 0 | X11: NOT BILLED
A12: 24S-054 | B12: C000015869 | C12: K162 | D12: I.S. 162 - BROOKLYN | E12: 1244202 | F12: 92352 | G12: CIP | H12: Walsh, Joseph | I12: PO 18 Asbestos Service | J12: Initial | K12: Initial | L12: 45475 | M12: 575 | S12: 0 | T12: 0 | X12: NOT BILLED
A13: 23S-129 | B13: C000015869 | C13: K163 | D13: P.S. 163 - BROOKLYN | E13: 1209543 | F13: 90141 | G13: CIP | H13: Bracamonte, Jesus | I13: LAP Construction Phase Services | J13: Initial | K13: Closed | L13: 45267 | M13: 11545 | N13: 45274 | O13: 45274 | P13: 326 | Q13: 46170 | R13: 3320.75 | S13: 0 | T13: -3320.75 | X13: UNPAID
A14: 23S-005 | B14: C000015869 | C14: K183 | D14: P.S. 183 - BROOKLYN | E14: 1160059 | F14: 87043 | G14: CIP | H14: Palermo, Albert | I14: PO 18 Asbestos Service | J14: Amendment | K14: WIP | L14: 44936 | M14: 5575 | S14: 0 | T14: 0 | X14: NOT BILLED
A15: 23S-120 | B15: C000015869 | C15: K224 | D15: P.S. 224 - BROOKLYN | E15: 1212815 | F15: 90349 | G15: CIP | H15: Vafiadis, Jon | I15: Special Program | J15: Initial | K15: Closed | L15: 45303 | M15: 1500 | N15: 45289 | O15: 45289 | P15: 329 | Q15: 46182 | R15: 933.13 | S15: 0 | T15: -933.13 | X15: UNPAID
B16: C000015869 | C16: K226 | D16: P.S. 126 - BROOKLYN | E16: 1317417 | G16: CIP | H16: Bracamonte, Jesus | I16: Special Program | J16: Initial | K16: Initial | L16: 45587 | M16: 4100 | S16: 0 | T16: 0 | X16: NOT BILLED
B17: C000015869 | C17: K226 | D17: P.S. 226 - BROOKLYN | E17: 1317422 | G17: CIP | H17: Bracamonte, Jesus | I17: Special Program | J17: Initial | K17: Initial | L17: 45587 | M17: 7800.06 | S17: 0 | T17: 0 | X17: NOT BILLED
A18: 24S-016 | B18: C000015869 | C18: K232 | D18: I.S. 232 - BROOKLYN | E18: 1223724 | F18: 89776 | G18: CIP | H18: Bracamonte, Jesus | I18: LAP Construction Phase Services | J18: Initial | K18: Initial | L18: 45364 | M18: 13900 | S18: 0 | T18: 0 | X18: NOT BILLED
A19: 24S-017 | B19: C000015869 | C19: K232 | D19: I.S. 232 - BROOKLYN | E19: 1223722 | F19: 89766 | G19: CIP | H19: Bracamonte, Jesus | I19: LAP Construction Phase Services | J19: Initial | K19: Initial | L19: 45365 | M19: 13900 | S19: 0 | T19: 0 | X19: NOT BILLED
A20: 24S-018 | B20: C000015869 | C20: K232 | D20: I.S. 232 - BROOKLYN | E20: 1223723 | F20: 89768 | G20: CIP | H20: Bracamonte, Jesus | I20: LAP Construction Phase Services | J20: Initial | K20: Closed | L20: 45365 | M20: 13900 | N20: 45365 | O20: 45887 | P20: 324 | Q20: 46150 | R20: 12493.53 | S20: 0 | T20: -12493.53 | X20: UNPAID
B21: C000015869 | C21: K233 | D21: P.S. 233 - BROOKLYN | E21: 1212811 | F21: 90339 | G21: CIP | H21: Vafiadis, Jon | I21: Special Program | J21: Initial | K21: Initial | L21: 45302 | M21: 1500 | S21: 0 | T21: 0 | X21: NOT BILLED
B22: C000015869 | C22: K244 | D22: P.S. 244 - BROOKLYN | E22: 1212812 | F22: 90338 | G22: CIP | H22: Vafiadis, Jon | I22: Special Program | J22: Initial | K22: Initial | L22: 45302 | M22: 1500 | S22: 0 | T22: 0 | X22: NOT BILLED
B23: C000015869 | C23: K250 | D23: P.S. 250 - BROOKLYN | E23: 1212797 | F23: 90325 | G23: CIP | H23: Vafiadis, Jon | I23: Special Program | J23: Initial | K23: Initial | L23: 45302 | M23: 1500 | S23: 0 | T23: 0 | X23: NOT BILLED
B24: C000015869 | C24: K260 | D24: P.S. 260 - BROOKLYN | E24: 1212816 | F24: 90348 | G24: CIP | H24: Vafiadis, Jon | I24: Special Program | J24: Initial | K24: Initial | L24: 45303 | M24: 1500 | S24: 0 | T24: 0 | X24: NOT BILLED
B25: C000015869 | C25: K273 | D25: P.S. 273 - BROOKLYN | E25: 1212817 | F25: 90347 | G25: CIP | H25: Vafiadis, Jon | I25: Special Program | J25: Initial | K25: Initial | L25: 45303 | M25: 1500 | S25: 0 | T25: 0 | X25: NOT BILLED
B26: C000015869 | C26: K276 | D26: P.S. 276 - BROOKLYN | E26: 1212812 | F26: 90337 | G26: CIP | H26: Vafiadis, Jon | I26: Special Program | J26: Initial | K26: Initial | L26: 45303 | M26: 1500 | S26: 0 | T26: 0 | X26: NOT BILLED
B27: C000015869 | C27: K279 | D27: P.S. 279 - BROOKLYN | E27: 1212814 | F27: 90336 | G27: CIP | H27: Vafiadis, Jon | I27: Special Program | J27: Initial | K27: Initial | L27: 45303 | M27: 1500 | S27: 0 | T27: 0 | X27: NOT BILLED
B28: C000015869 | C28: K287 | D28: P.S. 287 - BROOKLYN | E28: 1212544 | F28: 90316 | G28: CIP | H28: Vafiadis, Jon | I28: Special Program | J28: Initial | K28: Initial | L28: 45302 | M28: 1500 | S28: 0 | T28: 0 | X28: NOT BILLED
A29: 23S-075 | B29: C000015869 | C29: K335 | D29: P.S. 335 - BROOKLYN | E29: 1189823 | F29: 88936 | G29: CIP | H29: Palermo, Albert | I29: PO 18 Asbestos Service | J29: Initial | K29: WIP | L29: 45152 | M29: 575 | S29: 0 | T29: 0 | X29: NOT BILLED
B30: C000015869 | C30: K370 | D30: P.S. 370 - BROOKLYN | E30: 1317423 | G30: CIP | H30: Bracamonte, Jesus | I30: Special Program | J30: Initial | K30: Initial | L30: 45587 | M30: 7800.06 | S30: 0 | T30: 0 | X30: NOT BILLED
B31: C000015869 | C31: K615 | D31: E NY VOC HS OF TRANSIT TECH - BROOKLYN | E31: 1210691 | F31: 90158 | G31: CIP | H31: Palermo, Albert | I31: PO 18 Asbestos Service | J31: Amend 1 | K31: Initial | L31: 45279 | M31: 5375 | S31: 0 | T31: 0 | X31: NOT BILLED
A32: 24S-026 | B32: C000015869 | C32: K620 | D32: WILLIAM E GRADY VOC HS - BROOKLYN | E32: 1224928 | F32: 91352 | G32: CIP | H32: Bracamonte, Jesus | I32: LAP Construction Phase Services | J32: Initial | K32: Initial | L32: 45378 | M32: 12400 | S32: 0 | T32: 0 | X32: NOT BILLED
B33: C000015869 | C33: K851 | D33: P.S. 159 MINI SCHOOL - BROOKLYN | E33: 1320959 | F33: 93959 | G33: CIP | H33: Bracamonte, Jesus | I33: SAFE ACCESS | J33: Initial | K33: Initial | L33: 45609 | M33: 4100 | S33: 0 | T33: 0 | X33: NOT BILLED
A34: 24S-087 | B34: C000015869 | C34: K932 | D34: HIGH SCHOOL SUSPENSION CENTER - BROOKLYN | E34: 1305383 | F34: 92976 | G34: CIP | H34: Bracamonte, Jesus | I34: PO 18 Asbestos Service | J34: Initial | K34: Initial | L34: 45520 | M34: 4000 | S34: 0 | T34: 0 | X34: NOT BILLED
A35: 24S-148 | B35: C000015869 | C35: M061 | D35: P.S. 61 - MANHATTAN | E35: 1301457 | F35: 92654 | G35: CIP | H35: Lazicki, Rafal | I35: PO 18 Asbestos Service | J35: Initial | K35: Closed | L35: 45498 | M35: 575 | N35: 45911 | O35: 45913 | P35: 331 | Q35: 46182 | R35: 6371.31 | S35: 0 | T35: -6371.31 | X35: UNPAID
A36: 23S-117 | B36: C000015869 | C36: M115 | D36: P.S. 115 - MANHATTAN | E36: 1206373 | F36: 90058 | G36: CIP | H36: Alawamleh, Eman | I36: PO 18 Asbestos Service | J36: Initial | K36: WIP | L36: 45259 | M36: 7923.73 | N36: 45267 | O36: 45269 | P36: 320 | Q36: 46125 | R36: 8091.98 | S36: 0 | T36: -8091.98 | X36: UNPAID
A37: 24S-049 | B37: C000015869 | C37: M115 | D37: P.S. 115 - MANHATTAN | E37: 1241224 | F37: 92097 | G37: CIP | H37: Bracamonte, Jesus | I37: LAP Construction Phase Services | J37: Initial | K37: Initial | L37: 45455 | M37: 20200 | S37: 0 | T37: 0 | X37: NOT BILLED
B38: C000015869 | C38: M124 | D38: P.S. 124 (ECF) - MANHATTAN | E38: 1316025 | F38: 93166 | G38: CIP | I38: PO 18 Asbestos Service | J38: Initial | K38: Initial | L38: 45575 | M38: 575 | S38: 0 | T38: 0 | X38: NOT BILLED
B39: C000015869 | C39: M125 | D39: P.S. 125 - MANHATTAN | E39: 1335879 | F39: 94453 | G39: CIP | H39: Bracamonte, Jesus | I39: LAP Construction Phase Services | J39: Initial | K39: Initial | L39: 45708 | M39: 16200 | S39: 0 | T39: 0 | X39: NOT BILLED
A40: 24S-053 | B40: C000015869 | C40: M152 | D40: P.S. 152 - MANHATTAN | E40: 1243709 | F40: 92223 | G40: CIP | H40: Alawamleh, Eman | I40: PO 18 Asbestos Service | J40: Initial | K40: Initial | L40: 45343 | M40: 575 | S40: 0 | T40: 0 | X40: NOT BILLED
...

Sheet stg_job_list
A1: JOBID | B1: BID | C1: Description | D1: ServiceID | E1: Project_ID | F1: ContractNo | G1: SAI_Job_Status
A2: 22S-029 | B2: K014 | C2: LAP Construction Phase Services | D2: 85451 | E2: P026159 | F2: C000015869 | G2: Complete
A3: 22S-079 | B3: Q189 | C3: PO 18 Asbestos Service | D3: 86933 | E3: 133460 | F3: C000015869 | G3: Complete
A4: 23S-056 | B4: R445 | C4: PO 18 Asbestos Service | D4: 88731 | E4: 135678 | F4: C000015869 | G4: Complete
A5: 24S-114 | B5: M180 | C5: PO 18 Asbestos Service | D5: 93632 | E5: 141149 | F5: C000015869 | G5: Complete
A6: 25S-010 | B6: X107 | C6: PO 18 Asbestos Service | D6: 94758 | E6: 141770 | F6: C000015869 | G6: Complete

Sheet stg_payroll
A1: EMPLOYEE_NAME | B1: CODE | C1: HOURLY RATE | D1: DATE ON CHECK | E1: DATE WORKED | F1: WEEK ENDING DATE | G1: HOURS WORKED | H1: JOBID | I1: BUILDING LOCATION | J1: EXPENSES | K1: JOB TYPE | L1: LegacyEmpKey
A2: Igor Groysman | B2: 1 | C2: 38 | D2: 44961 | E2: 44910 | F2: 44912 | G2: 6.5 | H2: 22S-079 | I2: Q089 | K2: SCA | L2: =LOWER(SUBSTITUTE(stg_payroll!$A2," ","") & TEXT(stg_payroll!$B2,"00")) -> igorgroysman01
A3: Igor Groysman | B3: 1 | C3: 38 | D3: 44961 | E3: 44911 | F3: 44912 | G3: 4.5 | H3: 22S-079 | I3: Q089 | K3: SCA | L3: =LOWER(SUBSTITUTE(stg_payroll!$A3," ","") & TEXT(stg_payroll!$B3,"00")) -> igorgroysman01
A4: Ricardo Vilchez | B4: 1 | C4: 38 | D4: 45129 | E4: 45120 | F4: 45122 | G4: 11 | H4: 23S-056 | I4: R455 | J4: 6.55 | K4: SCA | L4: =LOWER(SUBSTITUTE(stg_payroll!$A4," ","") & TEXT(stg_payroll!$B4,"00")) -> ricardovilchez01
A5: Cornel Albu | B5: 1 | C5: 38 | D5: 45597 | E5: 45583 | F5: 45584 | G5: 7.5 | H5: 24S-114 | I5: M180 | K5: SCA | L5: =LOWER(SUBSTITUTE(stg_payroll!$A5," ","") & TEXT(stg_payroll!$B5,"00")) -> cornelalbu01
A6: Cornel Albu | B6: 1 | C6: 38 | D6: 45597 | E6: 45584 | F6: 45584 | G6: 18.5 | H6: 24S-114 | I6: M180 | K6: SCA | L6: =LOWER(SUBSTITUTE(stg_payroll!$A6," ","") & TEXT(stg_payroll!$B6,"00")) -> cornelalbu01
A7: Cornel Albu | B7: 3 | C7: 45 | D7: 45717 | E7: 45698 | F7: 45703 | G7: 9 | H7: 25S-010 | I7: X107 | K7: SCA | L7: =LOWER(SUBSTITUTE(stg_payroll!$A7," ","") & TEXT(stg_payroll!$B7,"00")) -> cornelalbu03
A8: Cornel Albu | B8: 1 | C8: 38 | D8: 45759 | E8: 45743 | F8: 45745 | G8: 5 | H8: 25S-010 | I8: X107 | K8: SCA | L8: =LOWER(SUBSTITUTE(stg_payroll!$A8," ","") & TEXT(stg_payroll!$B8,"00")) -> cornelalbu01
A9: Cornel Albu | B9: 1 | C9: 38 | D9: 45759 | E9: 45744 | F9: 45745 | G9: 6.5 | H9: 25S-010 | I9: X107 | K9: SCA | L9: =LOWER(SUBSTITUTE(stg_payroll!$A9," ","") & TEXT(stg_payroll!$B9,"00")) -> cornelalbu01
A10: Cornel Albu | B10: 1 | C10: 38 | D10: 45759 | E10: 45745 | F10: 45745 | G10: 21 | H10: 25S-010 | I10: X107 | J10: 27.76 | K10: SCA | L10: =LOWER(SUBSTITUTE(stg_payroll!$A10," ","") & TEXT(stg_payroll!$B10,"00")) -> cornelalbu01
A11: Cornel Albu | B11: 1 | C11: 38 | D11: 45759 | E11: 45750 | F11: 45752 | G11: 6 | H11: 25S-010 | I11: X107 | K11: SCA | L11: =LOWER(SUBSTITUTE(stg_payroll!$A11," ","") & TEXT(stg_payroll!$B11,"00")) -> cornelalbu01
A12: Cornel Albu | B12: 1 | C12: 38 | D12: 45759 | E12: 45751 | F12: 45752 | G12: 6.5 | H12: 25S-010 | I12: X107 | K12: SCA | L12: =LOWER(SUBSTITUTE(stg_payroll!$A12," ","") & TEXT(stg_payroll!$B12,"00")) -> cornelalbu01
A13: Cornel Albu | B13: 1 | C13: 38 | D13: 45759 | E13: 45752 | F13: 45752 | G13: 20.5 | H13: 25S-010 | I13: X107 | J13: 34.7 | K13: SCA | L13: =LOWER(SUBSTITUTE(stg_payroll!$A13," ","") & TEXT(stg_payroll!$B13,"00")) -> cornelalbu01
A14: Soslan Lazarov | B14: 1 | C14: 33 | D14: 45780 | E14: 45744 | F14: 45745 | G14: 5 | H14: 25S-010 | I14: X107 | K14: SCA | L14: =LOWER(SUBSTITUTE(stg_payroll!$A14," ","") & TEXT(stg_payroll!$B14,"00")) -> soslanlazarov01
A15: Soslan Lazarov | B15: 1 | C15: 33 | D15: 45780 | E15: 45745 | F15: 45745 | G15: 14 | H15: 25S-010 | I15: X107 | K15: SCA | L15: =LOWER(SUBSTITUTE(stg_payroll!$A15," ","") & TEXT(stg_payroll!$B15,"00")) -> soslanlazarov01
A16: Soslan Lazarov | B16: 1 | C16: 33 | D16: 45780 | E16: 45746 | F16: 45752 | G16: 15 | H16: 25S-010 | I16: X107 | J16: 9 | K16: SCA | L16: =LOWER(SUBSTITUTE(stg_payroll!$A16," ","") & TEXT(stg_payroll!$B16,"00")) -> soslanlazarov01
A17: Soslan Lazarov | B17: 1 | C17: 33 | D17: 45780 | E17: 45752 | F17: 45752 | G17: 14 | H17: 25S-010 | I17: X107 | K17: SCA | L17: =LOWER(SUBSTITUTE(stg_payroll!$A17," ","") & TEXT(stg_payroll!$B17,"00")) -> soslanlazarov01
A18: Soslan Lazarov | B18: 1 | C18: 33 | D18: 45780 | E18: 45753 | F18: 45759 | G18: 15 | H18: 25S-010 | I18: X107 | J18: 9 | K18: SCA | L18: =LOWER(SUBSTITUTE(stg_payroll!$A18," ","") & TEXT(stg_payroll!$B18,"00")) -> soslanlazarov01
A19: Soslan Lazarov | B19: 1 | C19: 33 | D19: 45780 | E19: 45757 | F19: 45759 | G19: 5 | H19: 25S-010 | I19: X107 | K19: SCA | L19: =LOWER(SUBSTITUTE(stg_payroll!$A19," ","") & TEXT(stg_payroll!$B19,"00")) -> soslanlazarov01
A20: Soslan Lazarov | B20: 1 | C20: 33 | D20: 45780 | E20: 45758 | F20: 45759 | G20: 5.5 | H20: 25S-010 | I20: X107 | K20: SCA | L20: =LOWER(SUBSTITUTE(stg_payroll!$A20," ","") & TEXT(stg_payroll!$B20,"00")) -> soslanlazarov01
A21: Soslan Lazarov | B21: 1 | C21: 33 | D21: 45780 | E21: 45759 | F21: 45759 | G21: 16.5 | H21: 25S-010 | I21: X107 | K21: SCA | L21: =LOWER(SUBSTITUTE(stg_payroll!$A21," ","") & TEXT(stg_payroll!$B21,"00")) -> soslanlazarov01
A22: Leon Groysman | B22: 1 | C22: 30 | D22: 45800 | E22: 45696 | F22: 45696 | G22: 7.5 | H22: 25S-010 | I22: X107 | J22: 6.95 | K22: SCA | L22: =LOWER(SUBSTITUTE(stg_payroll!$A22," ","") & TEXT(stg_payroll!$B22,"00")) -> leongroysman01
A23: Leon Groysman | B23: 1 | C23: 30 | D23: 45800 | E23: 45697 | F23: 45703 | G23: 8.5 | H23: 25S-010 | I23: X107 | J23: 6.95 | K23: SCA | L23: =LOWER(SUBSTITUTE(stg_payroll!$A23," ","") & TEXT(stg_payroll!$B23,"00")) -> leongroysman01
A24: Leon Groysman | B24: 1 | C24: 35 | D24: 46073 | E24: 45759 | F24: 45759 | G24: 16.5 | H24: 25S-010 | I24: X107 | J24: 13.9 | K24: SCA | L24: =LOWER(SUBSTITUTE(stg_payroll!$A24," ","") & TEXT(stg_payroll!$B24,"00")) -> leongroysman01
A25: Leon Groysman | B25: 1 | C25: 35 | D25: 46073 | E25: 45760 | F25: 45766 | G25: 16 | H25: 25S-010 | I25: X107 | J25: 13.9 | K25: SCA | L25: =LOWER(SUBSTITUTE(stg_payroll!$A25," ","") & TEXT(stg_payroll!$B25,"00")) -> leongroysman01
A26: Cornel Albu | B26: 1 | C26: 38 | E26: 45675 | G26: 6 | H26: 25S-002 | I26: X475 | K26: SCA | L26: =LOWER(SUBSTITUTE(stg_payroll!$A26," ","") & TEXT(stg_payroll!$B26,"00")) -> cornelalbu01
A27: Cornel Albu | B27: 1 | C27: 38 | E27: 45676 | G27: 6.5 | H27: 25S-002 | I27: X475 | K27: SCA | L27: =LOWER(SUBSTITUTE(stg_payroll!$A27," ","") & TEXT(stg_payroll!$B27,"00")) -> cornelalbu01
A28: Igor Groysman | B28: 1 | C28: 38 | E28: 44757 | G28: 10.5 | H28: 22S-029 | I28: K014 | K28: SCA | L28: =LOWER(SUBSTITUTE(stg_payroll!$A28," ","") & TEXT(stg_payroll!$B28,"00")) -> igorgroysman01
A29: Dimitri Bellos | B29: 3 | C29: 89 | E29: 44749 | G29: 6 | H29: 22S-029 | I29: K014 | K29: SCA | L29: =LOWER(SUBSTITUTE(stg_payroll!$A29," ","") & TEXT(stg_payroll!$B29,"00")) -> dimitribellos03

Sheet stg_employees
A1: EmpKey | B1: Last Name | C1: First Name | D1: Full Name | E1: EmployeeID | F1: EmployeeType | G1: Is_Active
A2: 1 | B2: Bellos | C2: Vasili | D2: =stg_employees!$C2&" "&stg_employees!$B2 -> Vasili Bellos | E2: VBE01 | F2: Salary | G2: 1
A3: 2 | B3: Bellos | C3: Dimitri | D3: =stg_employees!$C3&" "&stg_employees!$B3 -> Dimitri Bellos | E3: DBE01 | F3: Salary | G3: 1
A4: 3 | B4: Dros | C4: Patricia | D4: =stg_employees!$C4&" "&stg_employees!$B4 -> Patricia Dros | E4: PDR01 | F4: Hourly | G4: 1
A5: 4 | B5: Albu | C5: Cornel | D5: =stg_employees!$C5&" "&stg_employees!$B5 -> Cornel Albu | E5: CAL01 | F5: Contracted | G5: 1
A6: 5 | B6: Ablitsova | C6: Marina | D6: =stg_employees!$C6&" "&stg_employees!$B6 -> Marina Ablitsova | E6: MAB01 | F6: Contracted | G6: 1
A7: 6 | B7: Ciobanu | C7: Tatiana | D7: =stg_employees!$C7&" "&stg_employees!$B7 -> Tatiana Ciobanu | E7: TCI01 | F7: Contracted | G7: 1
A8: 7 | B8: Hung | C8: ChiFei | D8: =stg_employees!$C8&" "&stg_employees!$B8 -> ChiFei Hung | E8: CFE01 | F8: Contracted | G8: 1
A9: 8 | B9: Hung | C9: JoiFei | D9: =stg_employees!$C9&" "&stg_employees!$B9 -> JoiFei Hung | E9: JFE01 | F9: Contracted | G9: 1
A10: 9 | B10: Groysman | C10: Leon | D10: =stg_employees!$C10&" "&stg_employees!$B10 -> Leon Groysman | E10: LGR01 | F10: Contracted | G10: 1
A11: 10 | B11: Groysman | C11: Igor | D11: =stg_employees!$C11&" "&stg_employees!$B11 -> Igor Groysman | E11: IGR01 | F11: Contracted | G11: 1
A12: 11 | B12: Vilchez | C12: Ricardo | D12: =stg_employees!$C12&" "&stg_employees!$B12 -> Ricardo Vilchez | E12: RVI01 | F12: Contracted | G12: 0
A13: 12 | B13: Lazarov | C13: Soslan | D13: =stg_employees!$C13&" "&stg_employees!$B13 -> Soslan Lazarov | E13: SLA01 | F13: Contracted | G13: 1
... A23: 22 | B23: Jintchveladze | C23: Avtandil | D23: =stg_employees!$C23&" "&stg_employees!$B23 -> Avtandil Jintchveladze | E23: AJI01 | F23: Contracted | G23: 0

Sheet stg_labor_codes
A1: LaborClassKey | B1: JobCode | C1: JobTitle
A2: 1 | B2: 1 | C2: Asbestos Project Monitor
A3: 2 | B3: 2 | C3: Asbestos Inspector
A4: 3 | B4: 3 | C4: Asbestos Investigator
A5: 4 | B5: 4 | C5: Asbestos Project Designer
A6: 5 | B6: 5 | C6: Asbestos Project Manager
A7: 6 | B7: 6 | C7: Lead Inspector
A8: 7 | B8: 7 | C8: Lead Inspector/Risk Assessor
A9: 8 | B9: 8 | C9: Mold Inspector

Sheet stg_emp_rate_history
A1: LegacyEmpKey | B1: EmpName | C1: JobCode | D1: JobTitle | E1: ExpTier | F1: Rate_StartDate | G1: Rate_EndDate | H1: Rate
A2: adeniyiadeniran01 | B2: Adeniyi Adeniran | C2: 1 | D2: Asbestos Project Monitor | E2: 3 | F2: 45183 | G2: 45207 | H2: 33
A3: aleksandrgasis01 | B3: Aleksandr Gasis | C3: 1 | D3: Asbestos Project Monitor | E3: 3 | F3: 45536 | G3: =TODAY()+1 -> 46208 | H3: 38
A4: aleksandrtsvayg01 | B4: Aleksandr Tsvayg | C4: 1 | D4: Asbestos Project Monitor | E4: 3 | F4: 43466 | G4: 46124 | H4: 33
A5: aleksandrtsvayg01 | B5: Aleksandr Tsvayg | C5: 1 | D5: Asbestos Project Monitor | E5: 3 | F5: 46125 | G5: =TODAY()+1 -> 46208 | H5: 38
A6: chifeihung01 | B6: Chi Fei Hung | C6: 1 | D6: Asbestos Project Monitor | E6: 7 | F6: 43466 | G6: 46124 | H6: 38
A7: chifeihung02 | B7: Chi Fei Hung | C7: 2 | D7: Asbestos On Site Technical Air Testing | E7: 7 | F7: 43466 | G7: 46124 | H7: 38
A8: cornelalbu01 | B8: Cornel Albu | C8: 1 | D8: Asbestos Project Monitor | E8: 7 | F8: 43466 | G8: 46124 | H8: 38
A9: cornelalbu03 | B9: Cornel Albu | C9: 3 | D9: Asbestos Investigator | E9: 7 | F9: 43466 | G9: 46124 | H9: 45
A10: cornelalbu05 | B10: Cornel Albu | C10: 5 | D10: Asbestos Project Manager | E10: 7 | F10: 43466 | G10: =TODAY()+1 -> 46208 | H10: 45
A11: igorgroysman01 | B11: Igor Groysman | C11: 1 | D11: Asbestos Project Monitor | E11: 7 | F11: 43466 | G11: 46124 | H11: 38
A12: igorgroysman03 | B12: Igor Groysman | C12: 3 | D12: Asbestos Investigator | E12: 7 | F12: 43466 | G12: 46124 | H12: 45
A13: igorgroysman02 | B13: Igor Groysman | C13: 2 | D13: Asbestos On Site Technical Air Testing | E13: 7 | F13: 43466 | G13: 46124 | H13: 45
A14: ishahasan03 | B14: Isha Hasan | C14: 3 | D14: Asbestos Investigator | E14: 3 | F14: 43466 | G14: =TODAY()+1 -> 46208 | H14: 35
A15: joifeihung01 | B15: Joi Fei Hung | C15: 1 | D15: Asbestos Project Monitor | E15: 7 | F15: 43466 | G15: 46124 | H15: 38
A16: leongroysman01 | B16: Leon Groysman | C16: 1 | D16: Asbestos Project Monitor | E16: 3 | F16: 43466 | G16: 45864 | H16: 30
A17: leongroysman03 | B17: Leon Groysman | C17: 3 | D17: Asbestos Investigator | E17: 3 | F17: 43466 | G17: 45864 | H17: 30
A18: leongroysman03 | B18: Leon Groysman | C18: 3 | D18: Asbestos Investigator | E18: 3 | F18: 45865 | G18: 46124 | H18: 35
A19: leongroysman01 | B19: Leon Groysman | C19: 1 | D19: Asbestos Project Monitor | E19: 3 | F19: 45865 | G19: 46124 | H19: 35
A20: marinaablitsova01 | B20: Marina Ablitsova | C20: 1 | D20: Asbestos Project Monitor | E20: 3 | F20: 43466 | G20: 46124 | H20: 35
A21: maryanskira01 | B21: Maryan Skira | C21: 1 | D21: Asbestos Project Monitor | E21: 3 | F21: 43466 | G21: 46124 | H21: 35
A22: ricardovilchez06 | B22: Ricardo Vilchez | C22: 6 | D22: Lead Inspector | E22: 7 | F22: 43466 | G22: 45488 | H22: 45
A23: ricardovilchez01 | B23: Ricardo Vilchez | C23: 1 | D23: Asbestos Project Monitor | E23: 7 | F23: 43466 | G23: 45488 | H23: 38
A24: ricardovilchez02 | B24: Ricardo Vilchez | C24: 2 | D24: Asbestos On Site Technical Air Testing | E24: 7 | F24: 43466 | G24: 45488 | H24: 45
A25: ricardovilchez03 | B25: Ricardo Vilchez | C25: 3 | D25: Asbestos Investigator | E25: 7 | F25: 43466 | G25: 45488 | H25: 45
A26: shalvasagihashvili01 | B26: Shalva Sagihashvili | C26: 1 | D26: Asbestos Project Monitor | E26: 3 | F26: 44896 | G26: 45076 | H26: 38
... A28: tatianaciobanu01 | B28: Tatiana Ciobanu | C28: 1 | D28: Asbestos Project Monitor | E28: 3 | F28: 43466 | G28: 46124 | H28: 33
A29: tatianaciobanu01 | B29: Tatiana Ciobanu | C29: 1 | D29: Asbestos Project Monitor | E29: 7 | F29: 46125 | G29: =TODAY()+1 -> 46208 | H29: 38
A30: zviadinebieridze01 | B30: Zviadi Nebieridze | C30: 1 | D30: Asbestos Project Monitor | E30: 3 | F30: 43466 | G30: 46124 | H30: 33
A31: chifeihung01 | B31: Chi Fei Hung | C31: 1 | D31: Asbestos Project Monitor | E31: 7 | F31: 46125 | G31: =TODAY()+1 -> 46208 | H31: 42
A32: chifeihung02 | B32: Chi Fei Hung | C32: 2 | D32: Asbestos On Site Technical Air Testing | E32: 7 | F32: 46125 | G32: =TODAY()+1 -> 46208 | H32: 42
A33: cornelalbu01 | B33: Cornel Albu | C33: 1 | D33: Asbestos Project Monitor | E33: 7 | F33: 46125 | G33: =TODAY()+1 -> 46208 | H33: 42
A34: cornelalbu05 | B34: Cornel Albu | C34: 5 | D34: Asbestos Project Manager | E34: 7 | F34: 45658 | G34: =TODAY()+1 -> 46208 | H34: 45
A35: cornelalbu03 | B35: Cornel Albu | C35: 3 | D35: Asbestos Investigator | E35: 7 | F35: 46125 | G35: =TODAY()+1 -> 46208 | H35: 50
A36: ishahasan03 | B36: Isha Hasan | C36: 3 | D36: Asbestos Investigator | E36: 3 | F36: 43466 | G36: =TODAY()+1 -> 46208 | H36: 35
A37: igorgroysman01 | B37: Igor Groysman | C37: 1 | D37: Asbestos Project Monitor | E37: 7 | F37: 46125 | G37: =TODAY()+1 -> 46208 | H37: 42
A38: igorgroysman03 | B38: Igor Groysman | C38: 3 | D38: Asbestos Investigator | E38: 7 | F38: 46125 | G38: =TODAY()+1 -> 46208 | H38: 55
A39: igorgroysman02 | B39: Igor Groysman | C39: 2 | D39: Asbestos On Site Technical Air Testing | E39: 7 | F39: 46125 | G39: =TODAY()+1 -> 46208 | H39: 55
A40: joifeihung01 | B40: Joi Fei Hung | C40: 1 | D40: Asbestos Project Monitor | E40: 7 | F40: 46125 | G40: =TODAY()+1 -> 46208 | H40: 42
A41: leongroysman03 | B41: Leon Groysman | C41: 3 | D41: Asbestos Investigator | E41: 3 | F41: 46125 | G41: =TODAY()+1 -> 46208 | H41: 38
...

Sheet stg_lab_reports
A1: CLIENT_TYPE | B1: BID | C1: JOB_NO | D1: DATE OF REPORT | E1: BATCH NO | F1: SAMPLE TYPE | G1: QUANTITY | H1: TECHNICIAN | I1: FACILITY
A2: SCA | B2: X107 | C2: 25S-010 | D2: 45696 | E2: 25-02-233 | F2: Durings | G2: 4 | H2: Leon Groysman | I2: LTS
A3: SCA | B3: X107 | C3: 25S-010 | D3: 45696 | E3: 25-02-234 | F3: Finals | G3: 8 | H3: Leon Groysman | I3: LTS
A4: SCA | B4: X107 | C4: 25S-010 | D4: 45743 | E4: 25-03-812 | F4: Backgrounds | G4: 12 | H4: Cornel Albu | I4: LTS
A5: SCA | B5: X107 | C5: 25S-010 | D5: 45744 | E5: 25-03-908 | F5: Backgrounds | G5: 12 | H5: Soslan Lazarov | I5: LTS
A6: SCA | B6: X107 | C6: 25S-010 | D6: 45744 | E6: 25-03-871 | F6: Pre | G6: 12 | H6: Cornel Albu | I6: LTS
A7: SCA | B7: X107 | C7: 25S-010 | D7: 45744 | E7: 25-03-872 | F7: Durings | G7: 18 | H7: Cornel Albu | I7: LTS
A8: SCA | B8: X107 | C8: 25S-010 | D8: 45745 | E8: 25-03-909 | F8: Pre | G8: 12 | H8: Soslan Lazarov | I8: LTS
A9: SCA | B9: X107 | C9: 25S-010 | D9: 45745 | E9: 25-03-910 | F9: Durings | G9: 9 | H9: Soslan Lazarov | I9: LTS
A10: SCA | B10: X107 | C10: 25S-010 | D10: 45745 | E10: 25-03-873 | F10: Finals | G10: 12 | H10: Cornel Albu | I10: LTS
A11: SCA | B11: X107 | C11: 25S-010 | D11: 45745 | E11: 25-03-911 | F11: Finals | G11: 12 | H11: Soslan Lazarov | I11: LTS
A12: SCA | B12: X107 | C12: 25S-010 | D12: 45750 | E12: 25-04-082 | F12: Backgrounds | G12: 12 | H12: Cornel Albu | I12: LTS
A13: SCA | B13: X107 | C13: 25S-010 | D13: 45750 | E13: 25-04-081 | F13: Backgrounds | G13: 12 | H13: Cornel Albu | I13: LTS
... A38: SCA | B38: K014 | C38: 22S-029 | D38: 44757 | E38: 220715-32 | F38: DAF | G38: 7 | H38: Igor Groysman | I38: ALLAB

Sheet dim_date
A1: FullDate | B1: DateKey | C1: DayName | D1: MonthName | E1: Quarter | F1: Year | G1: WeekEndingDate | H1: WeekdayFlag
A2: =DATE(2019,1,1) -> 43466 | B2: =TEXT(A2,"yyyymmdd") -> 20190101 | C2: =TEXT(A2,"dddd") -> Tuesday | D2: =TEXT(A2,"mmmm") -> January | E2: ="Q"&ROUNDUP(MONTH(A2)/3,0) -> Q1 | F2: =YEAR(A2) -> 2019 | G2: =A2+(7-WEEKDAY(A2,1)) -> 43470 | H2: =IF(OR(TEXT(A2,"dddd")="Saturday",TEXT(A2,"dddd")="Sunday"),"No","Yes") -> Yes
A3: =A2+1 -> 43467 | B3: =TEXT(A3,"yyyymmdd") -> 20190102 | C3: =TEXT(A3,"dddd") -> Wednesday | D3: =TEXT(A3,"mmmm") -> January | E3: ="Q"&ROUNDUP(MONTH(A3)/3,0) -> Q1 | F3: =YEAR(A3) -> 2019 | G3: =A3+(7-WEEKDAY(A3,1)) -> 43470 | H3: =IF(OR(TEXT(A3,"dddd")="Saturday",TEXT(A3,"dddd")="Sunday"),"No","Yes") -> Yes
A4: =A3+1 -> 43468 | B4: =TEXT(A4,"yyyymmdd") -> 20190103 | C4: =TEXT(A4,"dddd") -> Thursday | D4: =TEXT(A4,"mmmm") -> January | E4: ="Q"&ROUNDUP(MONTH(A4)/3,0) -> Q1 | F4: =YEAR(A4) -> 2019 | G4: =A4+(7-WEEKDAY(A4,1)) -> 43470 | H4: =IF(OR(TEXT(A4,"dddd")="Saturday",TEXT(A4,"dddd")="Sunday"),"No","Yes") -> Yes
A5: =A4+1 -> 43469 | B5: =TEXT(A5,"yyyymmdd") -> 20190104 | C5: =TEXT(A5,"dddd") -> Friday | D5: =TEXT(A5,"mmmm") -> January | E5: ="Q"&ROUNDUP(MONTH(A5)/3,0) -> Q1 | F5: =YEAR(A5) -> 2019 | G5: =A5+(7-WEEKDAY(A5,1)) -> 43470 | H5: =IF(OR(TEXT(A5,"dddd")="Saturday",TEXT(A5,"dddd")="Sunday"),"No","Yes") -> Yes
A6: =A5+1 -> 43470 | B6: =TEXT(A6,"yyyymmdd") -> 20190105 | C6: =TEXT(A6,"dddd") -> Saturday | D6: =TEXT(A6,"mmmm") -> January | E6: ="Q"&ROUNDUP(MONTH(A6)/3,0) -> Q1 | F6: =YEAR(A6) -> 2019 | G6: =A6+(7-WEEKDAY(A6,1)) -> 43470 | H6: =IF(OR(TEXT(A6,"dddd")="Saturday",TEXT(A6,"dddd")="Sunday"),"No","Yes") -> No
A7: =A6+1 -> 43471 | B7: =TEXT(A7,"yyyymmdd") -> 20190106 | C7: =TEXT(A7,"dddd") -> Sunday | D7: =TEXT(A7,"mmmm") -> January | E7: ="Q"&ROUNDUP(MONTH(A7)/3,0) -> Q1 | F7: =YEAR(A7) -> 2019 | G7: =A7+(7-WEEKDAY(A7,1)) -> 43477 | H7: =IF(OR(TEXT(A7,"dddd")="Saturday",TEXT(A7,"dddd")="Sunday"),"No","Yes") -> No
A8: =A7+1 -> 43472 | B8: =TEXT(A8,"yyyymmdd") -> 20190107 | C8: =TEXT(A8,"dddd") -> Monday | D8: =TEXT(A8,"mmmm") -> January | E8: ="Q"&ROUNDUP(MONTH(A8)/3,0) -> Q1 | F8: =YEAR(A8) -> 2019 | G8: =A8+(7-WEEKDAY(A8,1)) -> 43477 | H8: =IF(OR(TEXT(A8,"dddd")="Saturday",TEXT(A8,"dddd")="Sunday"),"No","Yes") -> Yes
A9: =A8+1 -> 43473 | B9: =TEXT(A9,"yyyymmdd") -> 20190108 | C9: =TEXT(A9,"dddd") -> Tuesday | D9: =TEXT(A9,"mmmm") -> January | E9: ="Q"&ROUNDUP(MONTH(A9)/3,0) -> Q1 | F9: =YEAR(A9) -> 2019 | G9: =A9+(7-WEEKDAY(A9,1)) -> 43477 | H9: =IF(OR(TEXT(A9,"dddd")="Saturday",TEXT(A9,"dddd")="Sunday"),"No","Yes") -> Yes
A10: =A9+1 -> 43474 | B10: =TEXT(A10,"yyyymmdd") -> 20190109 | C10: =TEXT(A10,"dddd") -> Wednesday | D10: =TEXT(A10,"mmmm") -> January | E10: ="Q"&ROUNDUP(MONTH(A10)/3,0) -> Q1 | F10: =YEAR(A10) -> 2019 | G10: =A10+(7-WEEKDAY(A10,1)) -> 43477 | H10: =IF(OR(TEXT(A10,"dddd")="Saturday",TEXT(A10,"dddd")="Sunday"),"No","Yes") -> Yes
A11: =A10+1 -> 43475 | B11: =TEXT(A11,"yyyymmdd") -> 20190110 | C11: =TEXT(A11,"dddd") -> Thursday | D11: =TEXT(A11,"mmmm") -> January | E11: ="Q"&ROUNDUP(MONTH(A11)/3,0) -> Q1 | F11: =YEAR(A11) -> 2019 | G11: =A11+(7-WEEKDAY(A11,1)) -> 43477 | H11: =IF(OR(TEXT(A11,"dddd")="Saturday",TEXT(A11,"dddd")="Sunday"),"No","Yes") -> Yes
A12: =A11+1 -> 43476 | B12: =TEXT(A12,"yyyymmdd") -> 20190111 | C12: =TEXT(A12,"dddd") -> Friday | D12: =TEXT(A12,"mmmm") -> January | E12: ="Q"&ROUNDUP(MONTH(A12)/3,0) -> Q1 | F12: =YEAR(A12) -> 2019 | G12: =A12+(7-WEEKDAY(A12,1)) -> 43477 | H12: =IF(OR(TEXT(A12,"dddd")="Saturday",TEXT(A12,"dddd")="Sunday"),"No","Yes") -> Yes
A13: =A12+1 -> 43477 | B13: =TEXT(A13,"yyyymmdd") -> 20190112 | C13: =TEXT(A13,"dddd") -> Saturday | D13: =TEXT(A13,"mmmm") -> January | E13: ="Q"&ROUNDUP(MONTH(A13)/3,0) -> Q1 | F13: =YEAR(A13) -> 2019 | G13: =A13+(7-WEEKDAY(A13,1)) -> 43477 | H13: =IF(OR(TEXT(A13,"dddd")="Saturday",TEXT(A13,"dddd")="Sunday"),"No","Yes") -> No
A14: =A13+1 -> 43478 | B14: =TEXT(A14,"yyyymmdd") -> 20190113 | C14: =TEXT(A14,"dddd") -> Sunday | D14: =TEXT(A14,"mmmm") -> January | E14: ="Q"&ROUNDUP(MONTH(A14)/3,0) -> Q1 | F14: =YEAR(A14) -> 2019 | G14: =A14+(7-WEEKDAY(A14,1)) -> 43484 | H14: =IF(OR(TEXT(A14,"dddd")="Saturday",TEXT(A14,"dddd")="Sunday"),"No","Yes") -> No
... A2924: =A2923+1 -> 46388 | B2924: =TEXT(A2924,"yyyymmdd") -> 20270101 | C2924: =TEXT(A2924,"dddd") -> Friday | D2924: =TEXT(A2924,"mmmm") -> January | E2924: ="Q"&ROUNDUP(MONTH(A2924)/3,0) -> Q1 | F2924: =YEAR(A2924) -> 2027 | G2924: =A2924+(7-WEEKDAY(A2924,1)) -> 46389 | H2924: =IF(OR(TEXT(A2924,"dddd")="Saturday",TEXT(A2924,"dddd")="Sunday"),"No","Yes") -> Yes

Sheet dim_sai_rfp
A1: JobKey | B1: JobID | C1: ServiceID | D1: Contract_No | E1: SAI_RFP_No | F1: RFP_amount | G1: DateJobComplete | H1: RFP_Date
A2: 1 | B2: =stg_job_list!A2 -> 22S-029 | C2: =TRIM(stg_job_list!$D2) -> 85451 | D2: C000015869 | E2: 305 | F2: 3108.44 | G2: 44758 | H2: 46000
A3: 2 | B3: =stg_job_list!A3 -> 22S-079 | C3: =TRIM(stg_job_list!$D3) -> 86933 | D3: C000015869 | E3: 312 | F3: 1867.45 | G3: 44911 | H3: 46038
A4: 3 | B4: =stg_job_list!A4 -> 23S-056 | C4: =TRIM(stg_job_list!$D4) -> 88731 | D4: C000015869 | E4: 224 | F4: 2628.23 | G4: 45121 | H4: 45845
A5: 4 | B5: =stg_job_list!A5 -> 24S-114 | C5: =TRIM(stg_job_list!$D5) -> 93632 | D5: C000015869 | E5: 202 | F5: 4759.59 | G5: 45584 | H5: 45825
A6: 5 | B6: =stg_job_list!A6 -> 25S-010 | C6: =TRIM(stg_job_list!$D6) -> 94758 | D6: C000015869 | E6: 319 | F6: 39440.45 | G6: 45760 | H6: 46100

Sheet dim_job
A1: JobKey | B1: JobID | C1: BID | D1: Project_Description | E1: ServiceID | F1: Work_Auth_No | G1: PID | H1: Contract_No | I1: Initiation_Date | J1: Job_Status | K1: WA_Status
A2: 1 | B2: =stg_job_list!A2 -> 22S-029 | C2: =stg_job_list!$B2 -> K014 | D2: =stg_job_list!C2 -> LAP Construction Phase Services | E2: =stg_job_list!D2 -> 85451 | F2: 1229904 | G2: =stg_job_list!E2 -> P026159 | H2: =stg_job_list!F2 -> C000015869 | I2: 44749 | J2: =stg_job_list!G2 -> Complete | K2: Closed
A3: =A2+1 -> 2 | B3: =stg_job_list!A3 -> 22S-079 | C3: =stg_job_list!$B3 -> Q189 | D3: =stg_job_list!$C3 -> PO 18 Asbestos Service | E3: =stg_job_list!D3 -> 86933 | F3: 1157908 | G3: =stg_job_list!E3 -> 133460 | H3: =stg_job_list!F3 -> C000015869 | I3: 44910 | J3: =stg_job_list!G3 -> Complete | K3: Closed
A4: =A3+1 -> 3 | B4: =stg_job_list!A4 -> 23S-056 | C4: =stg_job_list!$B4 -> R445 | D4: =stg_job_list!$C4 -> PO 18 Asbestos Service | E4: =stg_job_list!D4 -> 88731 | F4: 1187909 | G4: =stg_job_list!E4 -> 135678 | H4: =stg_job_list!F4 -> C000015869 | I4: 45120 | J4: =stg_job_list!G4 -> Complete | K4: Closed
A5: =A4+1 -> 4 | B5: =stg_job_list!A5 -> 24S-114 | C5: =stg_job_list!$B5 -> M180 | D5: =stg_job_list!$C5 -> PO 18 Asbestos Service | E5: =stg_job_list!D5 -> 93632 | F5: 1315970 | G5: =stg_job_list!E5 -> 141149 | H5: =stg_job_list!F5 -> C000015869 | I5: 45575 | J5: =stg_job_list!G5 -> Complete | K5: Closed
A6: =A5+1 -> 5 | B6: =stg_job_list!A6 -> 25S-010 | C6: =stg_job_list!$B6 -> X107 | D6: =stg_job_list!$C6 -> PO 18 Asbestos Service | E6: =stg_job_list!D6 -> 94758 | F6: 1334935 | G6: =stg_job_list!E6 -> 141770 | H6: =stg_job_list!F6 -> C000015869 | I6: 45695 | J6: =stg_job_list!G6 -> Complete | K6: Closed

Sheet dim_labor_title
A1: LaborTitleKey | B1: Job_Code | C1: Job_Category | D1: Job_Title | E1: Title | F1: YearsExp | G1: Emp_YrsExp_Key
A2: 1 | B2: 1 | C2: Asbestos | D2: Project Monitor | E2: =dim_labor_title!$C2&" "&dim_labor_title!$D2 -> Asbestos Project Monitor | F2: 3 | G2: =dim_labor_title!$C2&" "&dim_labor_title!$D2&"|"&dim_labor_title!$F2 -> Asbestos Project Monitor|3
A3: 2 | B3: 2 | C3: Asbestos | D3: Air Testing | E3: =dim_labor_title!$C3&" "&dim_labor_title!$D3 -> Asbestos Air Testing | F3: 3 | G3: =dim_labor_title!$C3&" "&dim_labor_title!$D3&"|"&dim_labor_title!$F3 -> Asbestos Air Testing|3
A4: 3 | B4: 3 | C4: Asbestos | D4: Investigator | E4: =dim_labor_title!$C4&" "&dim_labor_title!$D4 -> Asbestos Investigator | F4: 3 | G4: =dim_labor_title!$C4&" "&dim_labor_title!$D4&"|"&dim_labor_title!$F4 -> Asbestos Investigator|3
A5: 4 | B5: 4 | C5: Asbestos | D5: Project Designer | E5: =dim_labor_title!$C5&" "&dim_labor_title!$D5 -> Asbestos Project Designer | F5: 3 | G5: =dim_labor_title!$C5&" "&dim_labor_title!$D5&"|"&dim_labor_title!$F5 -> Asbestos Project Designer|3
A6: 5 | B6: 5 | C6: Asbestos | D6: Project Manager | E6: =dim_labor_title!$C6&" "&dim_labor_title!$D6 -> Asbestos Project Manager | F6: 3 | G6: =dim_labor_title!$C6&" "&dim_labor_title!$D6&"|"&dim_labor_title!$F6 -> Asbestos Project Manager|3
A7: 6 | B7: 6 | C7: Lead | D7: Inspector | E7: =dim_labor_title!$C7&" "&dim_labor_title!$D7 -> Lead Inspector | F7: 3 | G7: =dim_labor_title!$C7&" "&dim_labor_title!$D7&"|"&dim_labor_title!$F7 -> Lead Inspector|3
A8: 7 | B8: 7 | C8: Lead | D8: Inspector / Risk Assessor | E8: =dim_labor_title!$C8&" "&dim_labor_title!$D8 -> Lead Inspector / Risk Assessor | F8: 3 | G8: =dim_labor_title!$C8&" "&dim_labor_title!$D8&"|"&dim_labor_title!$F8 -> Lead Inspector / Risk Assessor|3
A9: 8 | B9: 1 | C9: Asbestos | D9: Project Monitor | E9: =dim_labor_title!$C9&" "&dim_labor_title!$D9 -> Asbestos Project Monitor | F9: 7 | G9: =dim_labor_title!$C9&" "&dim_labor_title!$D9&"|"&dim_labor_title!$F9 -> Asbestos Project Monitor|7
A10: 9 | B10: 2 | C10: Asbestos | D10: Air Testing | E10: =dim_labor_title!$C10&" "&dim_labor_title!$D10 -> Asbestos Air Testing | F10: 7 | G10: =dim_labor_title!$C10&" "&dim_labor_title!$D10&"|"&dim_labor_title!$F10 -> Asbestos Air Testing|7
A11: 10 | B11: 3 | C11: Asbestos | D11: Investigator | E11: =dim_labor_title!$C11&" "&dim_labor_title!$D11 -> Asbestos Investigator | F11: 7 | G11: =dim_labor_title!$C11&" "&dim_labor_title!$D11&"|"&dim_labor_title!$F11 -> Asbestos Investigator|7
A12: 11 | B12: 4 | C12: Asbestos | D12: Project Designer | E12: =dim_labor_title!$C12&" "&dim_labor_title!$D12 -> Asbestos Project Designer | F12: 7 | G12: =dim_labor_title!$C12&" "&dim_labor_title!$D12&"|"&dim_labor_title!$F12 -> Asbestos Project Designer|7
A13: 12 | B13: 5 | C13: Asbestos | D13: Project Manager | E13: =dim_labor_title!$C13&" "&dim_labor_title!$D13 -> Asbestos Project Manager | F13: 7 | G13: =dim_labor_title!$C13&" "&dim_labor_title!$D13&"|"&dim_labor_title!$F13 -> Asbestos Project Manager|7
... A16: 15 | B16: 0 | C16: Office | D16: Admin | E16: =dim_labor_title!$C16&" "&dim_labor_title!$D16 -> Office Admin | F16: 3 | G16: =dim_labor_title!$C16&" "&dim_labor_title!$D16&"|"&dim_labor_title!$F16 -> Office Admin|3

Sheet dim_technician
A1: EmpIDKey | B1: Employee_Name | C1: First_Name | D1: Last_Name | E1: Job_Code | F1: SCA_Job_Title | G1: Yrs_Exp | H1: LegacyEmpKey
A2: 1 | B2: Cornel Albu | C2: Cornel | D2: Albu | E2: 1 | F2: {=XLOOKUP(dim_technician!$E2, dim_labor_title!$B$2:$B$16, dim_labor_title!$E$2:$E$16, "", 0)} -> Asbestos Project Monitor | G2: 7 | H2: =LOWER(dim_technician!$C2 & dim_technician!$D2 & TEXT(dim_technician!$E2, "00")) -> cornelalbu01
A3: 2 | B3: Cornel Albu | C3: Cornel | D3: Albu | E3: 2 | F3: {=XLOOKUP(dim_technician!$E3, dim_labor_title!$B$2:$B$16, dim_labor_title!$E$2:$E$16, "", 0)} -> Asbestos Air Testing | G3: 7 | H3: =LOWER(dim_technician!$C3 & dim_technician!$D3 & TEXT(dim_technician!$E3, "00")) -> cornelalbu02
A4: 3 | B4: Cornel Albu | C4: Cornel | D4: Albu | E4: 3 | F4: {=XLOOKUP(dim_technician!$E4, dim_labor_title!$B$2:$B$16, dim_labor_title!$E$2:$E$16, "", 0)} -> Asbestos Investigator | G4: 7 | H4: =LOWER(dim_technician!$C4 & dim_technician!$D4 & TEXT(dim_technician!$E4, "00")) -> cornelalbu03
A5: 4 | B5: Cornel Albu | C5: Cornel | D5: Albu | E5: 5 | F5: {=XLOOKUP(dim_technician!$E5, dim_labor_title!$B$2:$B$16, dim_labor_title!$E$2:$E$16, "", 0)} -> Asbestos Project Manager | G5: 7 | H5: =LOWER(dim_technician!$C5 & dim_technician!$D5 & TEXT(dim_technician!$E5, "00")) -> cornelalbu05
A6: 5 | B6: Marina Ablitsova | C6: Marina | D6: Ablitsova | E6: 1 | F6: {=XLOOKUP(dim_technician!$E6, dim_labor_title!$B$2:$B$16, dim_labor_title!$E$2:$E$16, "", 0)} -> Asbestos Project Monitor | G6: 3 | H6: =LOWER(dim_technician!$C6 & dim_technician!$D6 & TEXT(dim_technician!$E6, "00")) -> marinaablitsova01
A7: 6 | B7: Marina Ablitsova | C7: Marina | D7: Ablitsova | E7: 2 | F7: {=XLOOKUP(dim_technician!$E7, dim_labor_title!$B$2:$B$16, dim_labor_title!$E$2:$E$16, "", 0)} -> Asbestos Air Testing | G7: 3 | H7: =LOWER(dim_technician!$C7 & dim_technician!$D7 & TEXT(dim_technician!$E7, "00")) -> marinaablitsova02
A8: 7 | B8: Tatiana Ciobanu | C8: Tatiana | D8: Ciobanu | E8: 1 | F8: {=XLOOKUP(dim_technician!$E8, dim_labor_title!$B$2:$B$16, dim_labor_title!$E$2:$E$16, "", 0)} -> Asbestos Project Monitor | G8: 3 | H8: =LOWER(dim_technician!$C8 & dim_technician!$D8 & TEXT(dim_technician!$E8, "00")) -> tatianaciobanu01
A9: 8 | B9: Tatiana Ciobanu | C9: Tatiana | D9: Ciobanu | E9: 2 | F9: {=XLOOKUP(dim_technician!$E9, dim_labor_title!$B$2:$B$16, dim_labor_title!$E$2:$E$16, "", 0)} -> Asbestos Air Testing | G9: 3 | H9: =LOWER(dim_technician!$C9 & dim_technician!$D9 & TEXT(dim_technician!$E9, "00")) -> tatianaciobanu02
A10: 9 | B10: Chi Fei Hung | C10: ChiFei | D10: Hung | E10: 1 | F10: {=XLOOKUP(dim_technician!$E10, dim_labor_title!$B$2:$B$16, dim_labor_title!$E$2:$E$16, "", 0)} -> Asbestos Project Monitor | G10: 7 | H10: =LOWER(dim_technician!$C10 & dim_technician!$D10 & TEXT(dim_technician!$E10, "00")) -> chifeihung01
A11: 10 | B11: Chi Fei Hung | C11: ChiFei | D11: Hung | E11: 2 | F11: {=XLOOKUP(dim_technician!$E11, dim_labor_title!$B$2:$B$16, dim_labor_title!$E$2:$E$16, "", 0)} -> Asbestos Air Testing | G11: 7 | H11: =LOWER(dim_technician!$C11 & dim_technician!$D11 & TEXT(dim_technician!$E11, "00")) -> chifeihung02
A12: 11 | B12: Joi Fei Hung | C12: JoiFei | D12: Hung | E12: 1 | F12: {=XLOOKUP(dim_technician!$E12, dim_labor_title!$B$2:$B$16, dim_labor_title!$E$2:$E$16, "", 0)} -> Asbestos Project Monitor | G12: 7 | H12: =LOWER(dim_technician!$C12 & dim_technician!$D12 & TEXT(dim_technician!$E12, "00")) -> joifeihung01
A13: 12 | B13: Joi Fei Hung | C13: JoiFei | D13: Hung | E13: 2 | F13: {=XLOOKUP(dim_technician!$E13, dim_labor_title!$B$2:$B$16, dim_labor_title!$E$2:$E$16, "", 0)} -> Asbestos Air Testing | G13: 7 | H13: =LOWER(dim_technician!$C13 & dim_technician!$D13 & TEXT(dim_technician!$E13, "00")) -> joifeihung02
... A39: 38 | B39: Patricia Dros | C39: Patricia | D39: Dros | E39: 0 | F39: {=XLOOKUP(dim_technician!$E39, dim_labor_title!$B$2:$B$16, dim_labor_title!$E$2:$E$16, "", 0)} -> Office Admin | G39: 3 | H39: =LOWER(dim_technician!$C39 & dim_technician!$D39 & TEXT(dim_technician!$E39, "00")) -> patriciadros00

Sheet dim_emp_rate_history 
A1: EmpRateKey | B1: EmpKey | C1: Start_Date | D1: StartDateKey | E1: End_Date | F1: EndDateKey | G1: Hourly_Rate
B2: =TRIM(stg_emp_rate_history!$A2) -> adeniyiadeniran01 | C2: =stg_emp_rate_history!$F2 -> 45183 | D2: =TEXT(C2,"yyyymmdd") -> 20230914 | E2: =stg_emp_rate_history!$G2 -> 45207 | F2: =TEXT(E2,"yyyymmdd") -> 20231008 | G2: =stg_emp_rate_history!$H2 -> 33
B3: =TRIM(stg_emp_rate_history!$A3) -> aleksandrgasis01 | C3: =stg_emp_rate_history!$F3 -> 45536 | D3: =TEXT(C3,"yyyymmdd") -> 20240901 | E3: =stg_emp_rate_history!$G3 -> 46208 | F3: =TEXT(E3,"yyyymmdd") -> 20260705 | G3: =stg_emp_rate_history!$H3 -> 38
B4: =TRIM(stg_emp_rate_history!$A4) -> aleksandrtsvayg01 | C4: =stg_emp_rate_history!$F4 -> 43466 | D4: =TEXT(C4,"yyyymmdd") -> 20190101 | E4: =stg_emp_rate_history!$G4 -> 46124 | F4: =TEXT(E4,"yyyymmdd") -> 20260412 | G4: =stg_emp_rate_history!$H4 -> 33
B5: =TRIM(stg_emp_rate_history!$A5) -> aleksandrtsvayg01 | C5: =stg_emp_rate_history!$F5 -> 46125 | D5: =TEXT(C5,"yyyymmdd") -> 20260413 | E5: =stg_emp_rate_history!$G5 -> 46208 | F5: =TEXT(E5,"yyyymmdd") -> 20260705 | G5: =stg_emp_rate_history!$H5 -> 38
B6: =TRIM(stg_emp_rate_history!$A6) -> chifeihung01 | C6: =stg_emp_rate_history!$F6 -> 43466 | D6: =TEXT(C6,"yyyymmdd") -> 20190101 | E6: =stg_emp_rate_history!$G6 -> 46124 | F6: =TEXT(E6,"yyyymmdd") -> 20260412 | G6: =stg_emp_rate_history!$H6 -> 38
B7: =TRIM(stg_emp_rate_history!$A7) -> chifeihung02 | C7: =stg_emp_rate_history!$F7 -> 43466 | D7: =TEXT(C7,"yyyymmdd") -> 20190101 | E7: =stg_emp_rate_history!$G7 -> 46124 | F7: =TEXT(E7,"yyyymmdd") -> 20260412 | G7: =stg_emp_rate_history!$H7 -> 38
B8: =TRIM(stg_emp_rate_history!$A8) -> cornelalbu01 | C8: =stg_emp_rate_history!$F8 -> 43466 | D8: =TEXT(C8,"yyyymmdd") -> 20190101 | E8: =stg_emp_rate_history!$G8 -> 46124 | F8: =TEXT(E8,"yyyymmdd") -> 20260412 | G8: =stg_emp_rate_history!$H8 -> 38
B9: =TRIM(stg_emp_rate_history!$A9) -> cornelalbu03 | C9: =stg_emp_rate_history!$F9 -> 43466 | D9: =TEXT(C9,"yyyymmdd") -> 20190101 | E9: =stg_emp_rate_history!$G9 -> 46124 | F9: =TEXT(E9,"yyyymmdd") -> 20260412 | G9: =stg_emp_rate_history!$H9 -> 45
B10: =TRIM(stg_emp_rate_history!$A10) -> cornelalbu05 | C10: =stg_emp_rate_history!$F10 -> 43466 | D10: =TEXT(C10,"yyyymmdd") -> 20190101 | E10: =stg_emp_rate_history!$G10 -> 46208 | F10: =TEXT(E10,"yyyymmdd") -> 20260705 | G10: =stg_emp_rate_history!$H10 -> 45
B11: =TRIM(stg_emp_rate_history!$A11) -> igorgroysman01 | C11: =stg_emp_rate_history!$F11 -> 43466 | D11: =TEXT(C11,"yyyymmdd") -> 20190101 | E11: =stg_emp_rate_history!$G11 -> 46124 | F11: =TEXT(E11,"yyyymmdd") -> 20260412 | G11: =stg_emp_rate_history!$H11 -> 38
B12: =TRIM(stg_emp_rate_history!$A12) -> igorgroysman03 | C12: =stg_emp_rate_history!$F12 -> 43466 | D12: =TEXT(C12,"yyyymmdd") -> 20190101 | E12: =stg_emp_rate_history!$G12 -> 46124 | F12: =TEXT(E12,"yyyymmdd") -> 20260412 | G12: =stg_emp_rate_history!$H12 -> 45
B13: =TRIM(stg_emp_rate_history!$A13) -> igorgroysman02 | C13: =stg_emp_rate_history!$F13 -> 43466 | D13: =TEXT(C13,"yyyymmdd") -> 20190101 | E13: =stg_emp_rate_history!$G13 -> 46124 | F13: =TEXT(E13,"yyyymmdd") -> 20260412 | G13: =stg_emp_rate_history!$H13 -> 45
... B46: =TRIM(stg_emp_rate_history!$A46) -> zviadinebieridze01 | C46: =stg_emp_rate_history!$F46 -> 46125 | D46: =TEXT(C46,"yyyymmdd") -> 20260413 | E46: =stg_emp_rate_history!$G46 -> 46208 | F46: =TEXT(E46,"yyyymmdd") -> 20260705 | G46: =stg_emp_rate_history!$H46 -> 35
B47: =TRIM(stg_emp_rate_history!$A49) -> vasilisbellos03 | C47: =stg_emp_rate_history!$F49 -> 43466 | D47: =TEXT(C47,"yyyymmdd") -> 20190101 | E47: =stg_emp_rate_history!$G49 -> 46124 | F47: =TEXT(E47,"yyyymmdd") -> 20260412 | G47: =stg_emp_rate_history!$H49 -> 89
B48: =TRIM(stg_emp_rate_history!$A50) -> vasilisbellos03 | C48: =stg_emp_rate_history!$F50 -> 46125 | D48: =TEXT(C48,"yyyymmdd") -> 20260413 | E48: =stg_emp_rate_history!$G50 -> 46208 | F48: =TEXT(E48,"yyyymmdd") -> 20260705 | G48: =stg_emp_rate_history!$H50 -> 89
B49: =TRIM(stg_emp_rate_history!$A53) -> dimitribellos01 | C49: =stg_emp_rate_history!$F53 -> 43466 | D49: =TEXT(C49,"yyyymmdd") -> 20190101 | E49: =stg_emp_rate_history!$G53 -> 46124 | F49: =TEXT(E49,"yyyymmdd") -> 20260412 | G49: =stg_emp_rate_history!$H53 -> 89
B50: =TRIM(stg_emp_rate_history!$A54) -> dimitribellos01 | C50: =stg_emp_rate_history!$F54 -> 46125 | D50: =TEXT(C50,"yyyymmdd") -> 20260413 | E50: =stg_emp_rate_history!$G54 -> 46208 | F50: =TEXT(E50,"yyyymmdd") -> 20260705 | G50: =stg_emp_rate_history!$H54 -> 89
B51: =TRIM(stg_emp_rate_history!$A55) -> dimitribellos03 | C51: =stg_emp_rate_history!$F55 -> 43466 | D51: =TEXT(C51,"yyyymmdd") -> 20190101 | E51: =stg_emp_rate_history!$G55 -> 46124 | F51: =TEXT(E51,"yyyymmdd") -> 20260412 | G51: =stg_emp_rate_history!$H55 -> 89
B52: =TRIM(stg_emp_rate_history!$A56) -> patriciadros00 | C52: =stg_emp_rate_history!$F56 -> 44896 | D52: =TEXT(C52,"yyyymmdd") -> 20221201 | E52: =stg_emp_rate_history!$G56 -> 46208 | F52: =TEXT(E52,"yyyymmdd") -> 20260705 | G52: 28

Sheet dim_sca_labor_rate
A1: Contract_No | B1: Title Code | C1: SCA_Title_Description | D1: Category | E1: Job_Title | F1: SCA_JobTitle_Key | G1: Level | H1: Years of Experience | I1: Max Billable Hourly Rate | J1: Max Loaded Home Hourly Rate ($) | K1: Max Loaded Field Hourly Rate ($)
A2: C000015128 | B2: LMPABT1 | C2: Asbestos Certified Industrial Hygienist | D2: Asbestos | E2: Certified Industrial Hygienist | F2: =dim_sca_labor_rate!$A2&" "&dim_sca_labor_rate!$D2&" "&dim_sca_labor_rate!$E2&"|"&dim_sca_labor_rate!$H2 -> C000015128 Asbestos Certified Industrial Hygienist| | I2: 66.4 | J2: 166.664 | K2: 160.024
A3: C000015128 | B3: LMPABT9 | C3: Asbestos Inspector | D3: Asbestos | E3: Inspector | F3: =dim_sca_labor_rate!$A3&" "&dim_sca_labor_rate!$D3&" "&dim_sca_labor_rate!$E3&"|"&dim_sca_labor_rate!$H3 -> C000015128 Asbestos Inspector|7 | G3: A | H3: 7 | I3: 39.42 | J3: 98.9442 | K3: 95.0022
A4: C000015128 | B4: LMPABT10 | C4: Asbestos Inspector | D4: Asbestos | E4: Inspector | F4: =dim_sca_labor_rate!$A4&" "&dim_sca_labor_rate!$D4&" "&dim_sca_labor_rate!$E4&"|"&dim_sca_labor_rate!$H4 -> C000015128 Asbestos Inspector|3 | G4: B | H4: 3 | I4: 35.27 | J4: 88.5277 | K4: 85.0007
A5: C000015128 | B5: LMPABT4 | C5: Asbestos Investigator | D5: Asbestos | E5: Investigator | F5: =dim_sca_labor_rate!$A5&" "&dim_sca_labor_rate!$D5&" "&dim_sca_labor_rate!$E5&"|"&dim_sca_labor_rate!$H5 -> C000015128 Asbestos Investigator|7 | G5: A | H5: 7 | I5: 45.65 | J5: 114.5815 | K5: 110.0165
A6: C000015128 | B6: LMPABT5 | C6: Asbestos Investigator | D6: Asbestos | E6: Investigator | F6: =dim_sca_labor_rate!$A6&" "&dim_sca_labor_rate!$D6&" "&dim_sca_labor_rate!$E6&"|"&dim_sca_labor_rate!$H6 -> C000015128 Asbestos Investigator|3 | G6: B | H6: 3 | I6: 39.42 | J6: 98.9442 | K6: 95.0022
A7: C000015128 | B7: LMPABT11 | C7: Asbestos On Site Technical Air Testing | D7: Asbestos | E7: Air Testing | F7: =dim_sca_labor_rate!$A7&" "&dim_sca_labor_rate!$D7&" "&dim_sca_labor_rate!$E7&"|"&dim_sca_labor_rate!$H7 -> C000015128 Asbestos Air Testing|3 | G7: B | H7: 3 | I7: 33.2 | J7: 83.332 | K7: 80.012
A8: C000015128 | B8: LMPABT11 | C8: Asbestos On Site Technical Air Testing | D8: Asbestos | E8: Air Testing | F8: =dim_sca_labor_rate!$A8&" "&dim_sca_labor_rate!$D8&" "&dim_sca_labor_rate!$E8&"|"&dim_sca_labor_rate!$H8 -> C000015128 Asbestos Air Testing|7 | G8: A | H8: 7 | I8: 33.2 | J8: 83.332 | K8: 80.012
A9: C000015128 | B9: LMPABT6 | C9: Asbestos Project Designer | D9: Asbestos | E9: Project Designer | F9: =dim_sca_labor_rate!$A9&" "&dim_sca_labor_rate!$D9&" "&dim_sca_labor_rate!$E9&"|"&dim_sca_labor_rate!$H9 -> C000015128 Asbestos Project Designer|7 | G9: A | H9: 7 | I9: 45.65 | J9: 114.5815 | K9: 110.0165
A10: C000015128 | B10: LMPABT7 | C10: Asbestos Project Designer | D10: Asbestos | E10: Project Designer | F10: =dim_sca_labor_rate!$A10&" "&dim_sca_labor_rate!$D10&" "&dim_sca_labor_rate!$E10&"|"&dim_sca_labor_rate!$H10 -> C000015128 Asbestos Project Designer|3 | G10: B | H10: 3 | I10: 37.35 | J10: 93.7485 | K10: 90.0135
A11: C000015128 | B11: LMPABT2 | C11: Asbestos Project Manager | D11: Asbestos | E11: Project Manager | F11: =dim_sca_labor_rate!$A11&" "&dim_sca_labor_rate!$D11&" "&dim_sca_labor_rate!$E11&"|"&dim_sca_labor_rate!$H11 -> C000015128 Asbestos Project Manager|7 | G11: A | H11: 7 | I11: 58.1 | J11: 145.831 | K11: 140.021
A12: C000015128 | B12: LMPABT3 | C12: Asbestos Project Manager | D12: Asbestos | E12: Project Manager | F12: =dim_sca_labor_rate!$A12&" "&dim_sca_labor_rate!$D12&" "&dim_sca_labor_rate!$E12&"|"&dim_sca_labor_rate!$H12 -> C000015128 Asbestos Project Manager|3 | G12: B | H12: 3 | I12: 45.64 | J12: 114.5564 | K12: 109.9924
A13: C000015128 | B13: LMPABT8 | C13: Asbestos Project Monitor | D13: Asbestos | E13: Project Monitor | F13: =dim_sca_labor_rate!$A13&" "&dim_sca_labor_rate!$D13&" "&dim_sca_labor_rate!$E13&"|"&dim_sca_labor_rate!$H13 -> C000015128 Asbestos Project Monitor|7 | G13: A | H13: 7 | I13: 35.27 | J13: 88.5277 | K13: 85.0007
A14: C000015128 | B14: LMPABT8 | C14: Asbestos Project Monitor | D14: Asbestos | E14: Project Monitor | F14: =dim_sca_labor_rate!$A14&" "&dim_sca_labor_rate!$D14&" "&dim_sca_labor_rate!$E14&"|"&dim_sca_labor_rate!$H14 -> C000015128 Asbestos Project Monitor|3 | G14: B | H14: 3 | I14: 35.27 | J14: 88.5277 | K14: 85.0007
A15: C000015128 | B15: LMPGNT12 | C15: Computer Assisted Design Draftsperson | D15: Computer | E15: Assisted Design Draftsperson | F15: =dim_sca_labor_rate!$A15&" "&dim_sca_labor_rate!$D15&" "&dim_sca_labor_rate!$E15&"|"&dim_sca_labor_rate!$H15 -> C000015128 Computer Assisted Design Draftsperson|3 | G15: B | H15: 3 | I15: 29.05 | J15: 72.9155 | K15: 70.0105
A16: C000015128 | B16: LMPGNT13 | C16: Field Engineer P.E. | D16: Field | E16: Engineer P.E. | F16: =dim_sca_labor_rate!$A16&" "&dim_sca_labor_rate!$D16&" "&dim_sca_labor_rate!$E16&"|"&dim_sca_labor_rate!$H16 -> C000015128 Field Engineer P.E.| | I16: 68.46 | J16: 171.8346 | K16: 164.9886
A17: C000015128 | B17: LMPLDT21 | C17: Certified Lead Inspector | D17: Lead | E17: Inspector | F17: =dim_sca_labor_rate!$A17&" "&dim_sca_labor_rate!$D17&" "&dim_sca_labor_rate!$E17&"|"&dim_sca_labor_rate!$H17 -> C000015128 Lead Inspector|7 | G17: A | H17: 7 | I17: 37.34 | J17: 93.7234 | K17: 89.9894
A18: C000015128 | B18: LMPLDT22 | C18: Certified Lead Inspector | D18: Lead | E18: Inspector | F18: =dim_sca_labor_rate!$A18&" "&dim_sca_labor_rate!$D18&" "&dim_sca_labor_rate!$E18&"|"&dim_sca_labor_rate!$H18 -> C000015128 Lead Inspector|3 | G18: B | H18: 3 | I18: 31.12 | J18: 78.1112 | K18: 74.9992
A19: C000015128 | B19: LMPLDT19 | C19: Certified Lead Inspector / Risk Assessor | D19: Lead | E19: Inspector / Risk Assessor | F19: =dim_sca_labor_rate!$A19&" "&dim_sca_labor_rate!$D19&" "&dim_sca_labor_rate!$E19&"|"&dim_sca_labor_rate!$H19 -> C000015128 Lead Inspector / Risk Assessor|7 | G19: A | H19: 7 | I19: 45.64 | J19: 114.5564 | K19: 109.9924
A20: C000015128 | B20: LMPLDT20 | C20: Certified Lead Inspector / Risk Assessor | D20: Lead | E20: Inspector / Risk Assessor | F20: =dim_sca_labor_rate!$A20&" "&dim_sca_labor_rate!$D20&" "&dim_sca_labor_rate!$E20&"|"&dim_sca_labor_rate!$H20 -> C000015128 Lead Inspector / Risk Assessor|3 | G20: B | H20: 3 | I20: 39.42 | J20: 98.9442 | K20: 95.0022
A21: C000015128 | B21: LMPLDT23 | C21: Certified Lead Project Designer | D21: Lead | E21: Project Designer | F21: =dim_sca_labor_rate!$A21&" "&dim_sca_labor_rate!$D21&" "&dim_sca_labor_rate!$E21&"|"&dim_sca_labor_rate!$H21 -> C000015128 Lead Project Designer|7 | G21: A | H21: 7 | I21: 41.49 | J21: 104.1399 | K21: 99.9909
A22: C000015128 | B22: LMPLDT24 | C22: Certified Lead Project Designer | D22: Lead | E22: Project Designer | F22: =dim_sca_labor_rate!$A22&" "&dim_sca_labor_rate!$D22&" "&dim_sca_labor_rate!$E22&"|"&dim_sca_labor_rate!$H22 -> C000015128 Lead Project Designer|3 | G22: B | H22: 3 | I22: 31.12 | J22: 78.1112 | K22: 74.9992
